[2023-05-19T14:22:25.871+0530] {taskinstance.py:1125} INFO - Dependencies all met for dep_context=non-requeueable deps ti=<TaskInstance: mongodb_to_kafka_and_consumer.read_and_send_task manual__2023-05-19T06:47:16.784333+00:00 [queued]>
[2023-05-19T14:22:25.881+0530] {taskinstance.py:1125} INFO - Dependencies all met for dep_context=requeueable deps ti=<TaskInstance: mongodb_to_kafka_and_consumer.read_and_send_task manual__2023-05-19T06:47:16.784333+00:00 [queued]>
[2023-05-19T14:22:25.881+0530] {taskinstance.py:1331} INFO - Starting attempt 2 of 2
[2023-05-19T14:22:25.897+0530] {taskinstance.py:1350} INFO - Executing <Task(PythonOperator): read_and_send_task> on 2023-05-19 06:47:16.784333+00:00
[2023-05-19T14:22:25.902+0530] {standard_task_runner.py:57} INFO - Started process 21220 to run task
[2023-05-19T14:22:25.906+0530] {standard_task_runner.py:84} INFO - Running: ['airflow', 'tasks', 'run', 'mongodb_to_kafka_and_consumer', 'read_and_send_task', 'manual__2023-05-19T06:47:16.784333+00:00', '--job-id', '740', '--raw', '--subdir', 'DAGS_FOLDER/test1.py', '--cfg-path', '/tmp/tmpfk9zwp0o']
[2023-05-19T14:22:25.907+0530] {standard_task_runner.py:85} INFO - Job 740: Subtask read_and_send_task
[2023-05-19T14:22:25.956+0530] {task_command.py:410} INFO - Running <TaskInstance: mongodb_to_kafka_and_consumer.read_and_send_task manual__2023-05-19T06:47:16.784333+00:00 [running]> on host nizam-HP-15-Notebook-PC
[2023-05-19T14:22:26.041+0530] {taskinstance.py:1568} INFO - Exporting env vars: AIRFLOW_CTX_DAG_OWNER='airflow' AIRFLOW_CTX_DAG_ID='mongodb_to_kafka_and_consumer' AIRFLOW_CTX_TASK_ID='read_and_send_task' AIRFLOW_CTX_EXECUTION_DATE='2023-05-19T06:47:16.784333+00:00' AIRFLOW_CTX_TRY_NUMBER='2' AIRFLOW_CTX_DAG_RUN_ID='manual__2023-05-19T06:47:16.784333+00:00'
[2023-05-19T14:22:40.863+0530] {taskinstance.py:1847} ERROR - Task failed with exception
Traceback (most recent call last):
  File "/home/nizam/env_airflow/lib/python3.10/site-packages/pymongo/srv_resolver.py", line 89, in _resolve_uri
    results = _resolve(
  File "/home/nizam/env_airflow/lib/python3.10/site-packages/pymongo/srv_resolver.py", line 43, in _resolve
    return resolver.resolve(*args, **kwargs)
  File "/home/nizam/env_airflow/lib/python3.10/site-packages/dns/resolver.py", line 1368, in resolve
    return get_default_resolver().resolve(
  File "/home/nizam/env_airflow/lib/python3.10/site-packages/dns/resolver.py", line 1201, in resolve
    (nameserver, port, tcp, backoff) = resolution.next_nameserver()
  File "/home/nizam/env_airflow/lib/python3.10/site-packages/dns/resolver.py", line 704, in next_nameserver
    raise NoNameservers(request=self.request, errors=self.errors)
dns.resolver.NoNameservers: All nameservers failed to answer the query _mongodb._tcp.cluster0.vgtdfso.mongodb.net. IN SRV: Server 127.0.0.53 UDP port 53 answered The DNS operation timed out.; Server 127.0.0.53 UDP port 53 answered The DNS operation timed out.; Server 127.0.0.53 UDP port 53 answered The DNS operation timed out.; Server 127.0.0.53 UDP port 53 answered The DNS operation timed out.; Server 127.0.0.53 UDP port 53 answered The DNS operation timed out.; Server 127.0.0.53 UDP port 53 answered SERVFAIL

During handling of the above exception, another exception occurred:

Traceback (most recent call last):
  File "/home/nizam/env_airflow/lib/python3.10/site-packages/airflow/operators/python.py", line 181, in execute
    return_value = self.execute_callable()
  File "/home/nizam/env_airflow/lib/python3.10/site-packages/airflow/operators/python.py", line 198, in execute_callable
    return self.python_callable(*self.op_args, **self.op_kwargs)
  File "/home/nizam/airflow/dags/test1.py", line 25, in read_from_mongodb_and_send_to_kafka
    client = MongoClient(mongo_uri)
  File "/home/nizam/env_airflow/lib/python3.10/site-packages/pymongo/mongo_client.py", line 736, in __init__
    res = uri_parser.parse_uri(
  File "/home/nizam/env_airflow/lib/python3.10/site-packages/pymongo/uri_parser.py", line 542, in parse_uri
    nodes = dns_resolver.get_hosts()
  File "/home/nizam/env_airflow/lib/python3.10/site-packages/pymongo/srv_resolver.py", line 121, in get_hosts
    _, nodes = self._get_srv_response_and_hosts(True)
  File "/home/nizam/env_airflow/lib/python3.10/site-packages/pymongo/srv_resolver.py", line 101, in _get_srv_response_and_hosts
    results = self._resolve_uri(encapsulate_errors)
  File "/home/nizam/env_airflow/lib/python3.10/site-packages/pymongo/srv_resolver.py", line 97, in _resolve_uri
    raise ConfigurationError(str(exc))
pymongo.errors.ConfigurationError: All nameservers failed to answer the query _mongodb._tcp.cluster0.vgtdfso.mongodb.net. IN SRV: Server 127.0.0.53 UDP port 53 answered The DNS operation timed out.; Server 127.0.0.53 UDP port 53 answered The DNS operation timed out.; Server 127.0.0.53 UDP port 53 answered The DNS operation timed out.; Server 127.0.0.53 UDP port 53 answered The DNS operation timed out.; Server 127.0.0.53 UDP port 53 answered The DNS operation timed out.; Server 127.0.0.53 UDP port 53 answered SERVFAIL
[2023-05-19T14:22:40.878+0530] {taskinstance.py:1368} INFO - Marking task as FAILED. dag_id=mongodb_to_kafka_and_consumer, task_id=read_and_send_task, execution_date=20230519T064716, start_date=20230519T085225, end_date=20230519T085240
[2023-05-19T14:22:40.902+0530] {standard_task_runner.py:104} ERROR - Failed to execute job 740 for task read_and_send_task (All nameservers failed to answer the query _mongodb._tcp.cluster0.vgtdfso.mongodb.net. IN SRV: Server 127.0.0.53 UDP port 53 answered The DNS operation timed out.; Server 127.0.0.53 UDP port 53 answered The DNS operation timed out.; Server 127.0.0.53 UDP port 53 answered The DNS operation timed out.; Server 127.0.0.53 UDP port 53 answered The DNS operation timed out.; Server 127.0.0.53 UDP port 53 answered The DNS operation timed out.; Server 127.0.0.53 UDP port 53 answered SERVFAIL; 21220)
[2023-05-19T14:22:40.926+0530] {local_task_job_runner.py:232} INFO - Task exited with return code 1
[2023-05-19T14:22:40.950+0530] {taskinstance.py:2674} INFO - 0 downstream tasks scheduled from follow-on schedule check
