[2023-06-12T11:53:50.628+0530] {taskinstance.py:1125} INFO - Dependencies all met for dep_context=non-requeueable deps ti=<TaskInstance: storm_topooo.decision_task manual__2023-06-12T06:23:45.888868+00:00 [queued]>
[2023-06-12T11:53:50.637+0530] {taskinstance.py:1125} INFO - Dependencies all met for dep_context=requeueable deps ti=<TaskInstance: storm_topooo.decision_task manual__2023-06-12T06:23:45.888868+00:00 [queued]>
[2023-06-12T11:53:50.638+0530] {taskinstance.py:1331} INFO - Starting attempt 1 of 1
[2023-06-12T11:53:50.660+0530] {taskinstance.py:1350} INFO - Executing <Task(PythonOperator): decision_task> on 2023-06-12 06:23:45.888868+00:00
[2023-06-12T11:53:50.665+0530] {standard_task_runner.py:57} INFO - Started process 7991 to run task
[2023-06-12T11:53:50.669+0530] {standard_task_runner.py:84} INFO - Running: ['airflow', 'tasks', 'run', 'storm_topooo', 'decision_task', 'manual__2023-06-12T06:23:45.888868+00:00', '--job-id', '918', '--raw', '--subdir', 'DAGS_FOLDER/dag.py', '--cfg-path', '/tmp/tmpkmrlvgdq']
[2023-06-12T11:53:50.671+0530] {standard_task_runner.py:85} INFO - Job 918: Subtask decision_task
[2023-06-12T11:53:50.736+0530] {task_command.py:410} INFO - Running <TaskInstance: storm_topooo.decision_task manual__2023-06-12T06:23:45.888868+00:00 [running]> on host nizam-HP-15-Notebook-PC
[2023-06-12T11:53:50.825+0530] {taskinstance.py:1568} INFO - Exporting env vars: AIRFLOW_CTX_DAG_OWNER='airflow' AIRFLOW_CTX_DAG_ID='storm_topooo' AIRFLOW_CTX_TASK_ID='decision_task' AIRFLOW_CTX_EXECUTION_DATE='2023-06-12T06:23:45.888868+00:00' AIRFLOW_CTX_TRY_NUMBER='1' AIRFLOW_CTX_DAG_RUN_ID='manual__2023-06-12T06:23:45.888868+00:00'
[2023-06-12T11:53:50.826+0530] {taskinstance.py:1847} ERROR - Task failed with exception
Traceback (most recent call last):
  File "/home/nizam/env_airflow/lib/python3.10/site-packages/airflow/operators/python.py", line 181, in execute
    return_value = self.execute_callable()
  File "/home/nizam/env_airflow/lib/python3.10/site-packages/airflow/operators/python.py", line 198, in execute_callable
    return self.python_callable(*self.op_args, **self.op_kwargs)
TypeError: send_email() missing 1 required positional argument: 'context'
[2023-06-12T11:53:50.833+0530] {taskinstance.py:1368} INFO - Marking task as FAILED. dag_id=storm_topooo, task_id=decision_task, execution_date=20230612T062345, start_date=20230612T062350, end_date=20230612T062350
[2023-06-12T11:53:50.850+0530] {standard_task_runner.py:104} ERROR - Failed to execute job 918 for task decision_task (send_email() missing 1 required positional argument: 'context'; 7991)
[2023-06-12T11:53:50.882+0530] {local_task_job_runner.py:232} INFO - Task exited with return code 1
[2023-06-12T11:53:50.908+0530] {taskinstance.py:2674} INFO - 0 downstream tasks scheduled from follow-on schedule check
