[2023-05-16T16:45:39.953+0530] {taskinstance.py:1125} INFO - Dependencies all met for dep_context=non-requeueable deps ti=<TaskInstance: storm_topology.launch_topology manual__2023-05-16T11:15:22.238801+00:00 [queued]>
[2023-05-16T16:45:39.962+0530] {taskinstance.py:1125} INFO - Dependencies all met for dep_context=requeueable deps ti=<TaskInstance: storm_topology.launch_topology manual__2023-05-16T11:15:22.238801+00:00 [queued]>
[2023-05-16T16:45:39.962+0530] {taskinstance.py:1331} INFO - Starting attempt 1 of 2
[2023-05-16T16:45:39.980+0530] {taskinstance.py:1350} INFO - Executing <Task(PythonOperator): launch_topology> on 2023-05-16 11:15:22.238801+00:00
[2023-05-16T16:45:39.986+0530] {standard_task_runner.py:57} INFO - Started process 48200 to run task
[2023-05-16T16:45:39.991+0530] {standard_task_runner.py:84} INFO - Running: ['airflow', 'tasks', 'run', 'storm_topology', 'launch_topology', 'manual__2023-05-16T11:15:22.238801+00:00', '--job-id', '281', '--raw', '--subdir', 'DAGS_FOLDER/bolt.py', '--cfg-path', '/tmp/tmpz7ihovk1']
[2023-05-16T16:45:39.993+0530] {standard_task_runner.py:85} INFO - Job 281: Subtask launch_topology
[2023-05-16T16:45:40.065+0530] {task_command.py:410} INFO - Running <TaskInstance: storm_topology.launch_topology manual__2023-05-16T11:15:22.238801+00:00 [running]> on host nizam-HP-15-Notebook-PC
[2023-05-16T16:45:40.165+0530] {taskinstance.py:1568} INFO - Exporting env vars: AIRFLOW_CTX_DAG_OWNER='airflow' AIRFLOW_CTX_DAG_ID='storm_topology' AIRFLOW_CTX_TASK_ID='launch_topology' AIRFLOW_CTX_EXECUTION_DATE='2023-05-16T11:15:22.238801+00:00' AIRFLOW_CTX_TRY_NUMBER='1' AIRFLOW_CTX_DAG_RUN_ID='manual__2023-05-16T11:15:22.238801+00:00'
[2023-05-16T16:45:53.261+0530] {taskinstance.py:1847} ERROR - Task failed with exception
Traceback (most recent call last):
  File "/home/nizam/env_airflow/lib/python3.10/site-packages/airflow/operators/python.py", line 181, in execute
    return_value = self.execute_callable()
  File "/home/nizam/env_airflow/lib/python3.10/site-packages/airflow/operators/python.py", line 198, in execute_callable
    return self.python_callable(*self.op_args, **self.op_kwargs)
  File "/home/nizam/airflow/dags/bolt.py", line 24, in launch_storm_topology
    kwargs['ti'].success()
AttributeError: 'TaskInstance' object has no attribute 'success'
[2023-05-16T16:45:53.270+0530] {taskinstance.py:1368} INFO - Marking task as UP_FOR_RETRY. dag_id=storm_topology, task_id=launch_topology, execution_date=20230516T111522, start_date=20230516T111539, end_date=20230516T111553
[2023-05-16T16:45:53.286+0530] {standard_task_runner.py:104} ERROR - Failed to execute job 281 for task launch_topology ('TaskInstance' object has no attribute 'success'; 48200)
[2023-05-16T16:45:53.320+0530] {local_task_job_runner.py:232} INFO - Task exited with return code 1
[2023-05-16T16:45:53.335+0530] {taskinstance.py:2674} INFO - 0 downstream tasks scheduled from follow-on schedule check
