[2023-06-11T10:29:00.931+0530] {taskinstance.py:1125} INFO - Dependencies all met for dep_context=non-requeueable deps ti=<TaskInstance: email_automation.send_email manual__2023-06-11T04:58:53.339768+00:00 [queued]>
[2023-06-11T10:29:00.940+0530] {taskinstance.py:1125} INFO - Dependencies all met for dep_context=requeueable deps ti=<TaskInstance: email_automation.send_email manual__2023-06-11T04:58:53.339768+00:00 [queued]>
[2023-06-11T10:29:00.941+0530] {taskinstance.py:1331} INFO - Starting attempt 1 of 1
[2023-06-11T10:29:00.959+0530] {taskinstance.py:1350} INFO - Executing <Task(PythonOperator): send_email> on 2023-06-11 04:58:53.339768+00:00
[2023-06-11T10:29:00.962+0530] {standard_task_runner.py:57} INFO - Started process 6618 to run task
[2023-06-11T10:29:00.966+0530] {standard_task_runner.py:84} INFO - Running: ['airflow', 'tasks', 'run', 'email_automation', 'send_email', 'manual__2023-06-11T04:58:53.339768+00:00', '--job-id', '895', '--raw', '--subdir', 'DAGS_FOLDER/emailoperator_demo.py', '--cfg-path', '/tmp/tmp7kubhao2']
[2023-06-11T10:29:00.968+0530] {standard_task_runner.py:85} INFO - Job 895: Subtask send_email
[2023-06-11T10:29:01.031+0530] {task_command.py:410} INFO - Running <TaskInstance: email_automation.send_email manual__2023-06-11T04:58:53.339768+00:00 [running]> on host nizam-HP-15-Notebook-PC
[2023-06-11T10:29:01.204+0530] {taskinstance.py:1568} INFO - Exporting env vars: AIRFLOW_CTX_DAG_EMAIL='officialark11@gmail.com' AIRFLOW_CTX_DAG_OWNER='airflow' AIRFLOW_CTX_DAG_ID='email_automation' AIRFLOW_CTX_TASK_ID='send_email' AIRFLOW_CTX_EXECUTION_DATE='2023-06-11T04:58:53.339768+00:00' AIRFLOW_CTX_TRY_NUMBER='1' AIRFLOW_CTX_DAG_RUN_ID='manual__2023-06-11T04:58:53.339768+00:00'
[2023-06-11T10:29:08.112+0530] {taskinstance.py:1847} ERROR - Task failed with exception
Traceback (most recent call last):
  File "/home/nizam/env_airflow/lib/python3.10/site-packages/airflow/operators/python.py", line 181, in execute
    return_value = self.execute_callable()
  File "/home/nizam/env_airflow/lib/python3.10/site-packages/airflow/operators/python.py", line 198, in execute_callable
    return self.python_callable(*self.op_args, **self.op_kwargs)
  File "/home/nizam/airflow/dags/emailoperator_demo.py", line 208, in init_email
    send_email_basic(sender, recipients, subject)
  File "/home/nizam/airflow/dags/emailoperator_demo.py", line 201, in send_email_basic
    server.login(sender_email, password)
  File "/usr/lib/python3.10/smtplib.py", line 750, in login
    raise last_exception
  File "/usr/lib/python3.10/smtplib.py", line 739, in login
    (code, resp) = self.auth(
  File "/usr/lib/python3.10/smtplib.py", line 662, in auth
    raise SMTPAuthenticationError(code, resp)
smtplib.SMTPAuthenticationError: (535, b'5.7.8 Username and Password not accepted. Learn more at\n5.7.8  https://support.google.com/mail/?p=BadCredentials h13-20020a17090a3d0d00b0025954958e06sm5588450pjc.18 - gsmtp')
[2023-06-11T10:29:08.126+0530] {taskinstance.py:1368} INFO - Marking task as FAILED. dag_id=email_automation, task_id=send_email, execution_date=20230611T045853, start_date=20230611T045900, end_date=20230611T045908
[2023-06-11T10:29:08.155+0530] {base.py:73} INFO - Using connection ID 'smtp_default' for task execution.
[2023-06-11T10:29:08.156+0530] {email.py:268} INFO - Email alerting: attempt 1
[2023-06-11T10:29:14.256+0530] {base.py:73} INFO - Using connection ID 'smtp_default' for task execution.
[2023-06-11T10:29:14.257+0530] {email.py:268} INFO - Email alerting: attempt 1
[2023-06-11T10:29:21.145+0530] {taskinstance.py:1912} ERROR - Failed to send email to: ['officialark11@gmail.com']
Traceback (most recent call last):
  File "/home/nizam/env_airflow/lib/python3.10/site-packages/airflow/models/taskinstance.py", line 1430, in _run_raw_task
    self._execute_task_with_callbacks(context, test_mode)
  File "/home/nizam/env_airflow/lib/python3.10/site-packages/airflow/models/taskinstance.py", line 1581, in _execute_task_with_callbacks
    result = self._execute_task(context, task_orig)
  File "/home/nizam/env_airflow/lib/python3.10/site-packages/airflow/models/taskinstance.py", line 1651, in _execute_task
    result = execute_callable(context=context)
  File "/home/nizam/env_airflow/lib/python3.10/site-packages/airflow/operators/python.py", line 181, in execute
    return_value = self.execute_callable()
  File "/home/nizam/env_airflow/lib/python3.10/site-packages/airflow/operators/python.py", line 198, in execute_callable
    return self.python_callable(*self.op_args, **self.op_kwargs)
  File "/home/nizam/airflow/dags/emailoperator_demo.py", line 208, in init_email
    send_email_basic(sender, recipients, subject)
  File "/home/nizam/airflow/dags/emailoperator_demo.py", line 201, in send_email_basic
    server.login(sender_email, password)
  File "/usr/lib/python3.10/smtplib.py", line 750, in login
    raise last_exception
  File "/usr/lib/python3.10/smtplib.py", line 739, in login
    (code, resp) = self.auth(
  File "/usr/lib/python3.10/smtplib.py", line 662, in auth
    raise SMTPAuthenticationError(code, resp)
smtplib.SMTPAuthenticationError: (535, b'5.7.8 Username and Password not accepted. Learn more at\n5.7.8  https://support.google.com/mail/?p=BadCredentials h13-20020a17090a3d0d00b0025954958e06sm5588450pjc.18 - gsmtp')

During handling of the above exception, another exception occurred:

Traceback (most recent call last):
  File "/home/nizam/env_airflow/lib/python3.10/site-packages/airflow/models/taskinstance.py", line 2318, in email_alert
    send_email(task.email, subject, html_content)
  File "/home/nizam/env_airflow/lib/python3.10/site-packages/airflow/utils/email.py", line 78, in send_email
    return backend(
  File "/home/nizam/env_airflow/lib/python3.10/site-packages/airflow/utils/email.py", line 152, in send_email_smtp
    send_mime_email(e_from=mail_from, e_to=recipients, mime_msg=msg, conn_id=conn_id, dryrun=dryrun)
  File "/home/nizam/env_airflow/lib/python3.10/site-packages/airflow/utils/email.py", line 279, in send_mime_email
    smtp_conn.login(smtp_user, smtp_password)
  File "/usr/lib/python3.10/smtplib.py", line 750, in login
    raise last_exception
  File "/usr/lib/python3.10/smtplib.py", line 739, in login
    (code, resp) = self.auth(
  File "/usr/lib/python3.10/smtplib.py", line 662, in auth
    raise SMTPAuthenticationError(code, resp)
smtplib.SMTPAuthenticationError: (535, b'5.7.8 Username and Password not accepted. Learn more at\n5.7.8  https://support.google.com/mail/?p=BadCredentials z189-20020a6333c6000000b005344b30d449sm5197547pgz.86 - gsmtp')

During handling of the above exception, another exception occurred:

Traceback (most recent call last):
  File "/home/nizam/env_airflow/lib/python3.10/site-packages/airflow/models/taskinstance.py", line 1910, in handle_failure
    self.email_alert(error, task)
  File "/home/nizam/env_airflow/lib/python3.10/site-packages/airflow/models/taskinstance.py", line 2320, in email_alert
    send_email(task.email, subject, html_content_err)
  File "/home/nizam/env_airflow/lib/python3.10/site-packages/airflow/utils/email.py", line 78, in send_email
    return backend(
  File "/home/nizam/env_airflow/lib/python3.10/site-packages/airflow/utils/email.py", line 152, in send_email_smtp
    send_mime_email(e_from=mail_from, e_to=recipients, mime_msg=msg, conn_id=conn_id, dryrun=dryrun)
  File "/home/nizam/env_airflow/lib/python3.10/site-packages/airflow/utils/email.py", line 279, in send_mime_email
    smtp_conn.login(smtp_user, smtp_password)
  File "/usr/lib/python3.10/smtplib.py", line 750, in login
    raise last_exception
  File "/usr/lib/python3.10/smtplib.py", line 739, in login
    (code, resp) = self.auth(
  File "/usr/lib/python3.10/smtplib.py", line 662, in auth
    raise SMTPAuthenticationError(code, resp)
smtplib.SMTPAuthenticationError: (535, b'5.7.8 Username and Password not accepted. Learn more at\n5.7.8  https://support.google.com/mail/?p=BadCredentials bg1-20020a17090b0d8100b0024752ff8061sm5284164pjb.12 - gsmtp')
[2023-06-11T10:29:21.170+0530] {standard_task_runner.py:104} ERROR - Failed to execute job 895 for task send_email ((535, b'5.7.8 Username and Password not accepted. Learn more at\n5.7.8  https://support.google.com/mail/?p=BadCredentials h13-20020a17090a3d0d00b0025954958e06sm5588450pjc.18 - gsmtp'); 6618)
[2023-06-11T10:29:21.193+0530] {local_task_job_runner.py:232} INFO - Task exited with return code 1
[2023-06-11T10:29:21.222+0530] {taskinstance.py:2674} INFO - 0 downstream tasks scheduled from follow-on schedule check
