[2023-05-10T17:01:09.357+0530] {taskinstance.py:1115} INFO - Dependencies not met for <TaskInstance: mongodb_to_kafka_and_consumer.consume_from_kafka_task scheduled__2023-05-10T00:00:00+00:00 [up_for_retry]>, dependency 'Not In Retry Period' FAILED: Task is not ready for retry yet but will be retried automatically. Current date is 2023-05-10T11:31:09.357015+00:00 and task will be retried at 2023-05-10T11:36:04.021268+00:00.
[2023-05-10T17:01:09.364+0530] {local_task_job_runner.py:161} INFO - Task is not able to be run
[2023-05-11T00:20:41.050+0530] {taskinstance.py:1125} INFO - Dependencies all met for dep_context=non-requeueable deps ti=<TaskInstance: mongodb_to_kafka_and_consumer.consume_from_kafka_task scheduled__2023-05-10T00:00:00+00:00 [queued]>
[2023-05-11T00:20:41.058+0530] {taskinstance.py:1125} INFO - Dependencies all met for dep_context=requeueable deps ti=<TaskInstance: mongodb_to_kafka_and_consumer.consume_from_kafka_task scheduled__2023-05-10T00:00:00+00:00 [queued]>
[2023-05-11T00:20:41.059+0530] {taskinstance.py:1331} INFO - Starting attempt 2 of 2
[2023-05-11T00:20:41.075+0530] {taskinstance.py:1350} INFO - Executing <Task(PythonOperator): consume_from_kafka_task> on 2023-05-10 00:00:00+00:00
[2023-05-11T00:20:41.080+0530] {standard_task_runner.py:57} INFO - Started process 6897 to run task
[2023-05-11T00:20:41.085+0530] {standard_task_runner.py:84} INFO - Running: ['airflow', 'tasks', 'run', 'mongodb_to_kafka_and_consumer', 'consume_from_kafka_task', 'scheduled__2023-05-10T00:00:00+00:00', '--job-id', '36', '--raw', '--subdir', 'DAGS_FOLDER/mongokafka.py', '--cfg-path', '/tmp/tmp118s1_ll']
[2023-05-11T00:20:41.086+0530] {standard_task_runner.py:85} INFO - Job 36: Subtask consume_from_kafka_task
[2023-05-11T00:20:41.137+0530] {task_command.py:410} INFO - Running <TaskInstance: mongodb_to_kafka_and_consumer.consume_from_kafka_task scheduled__2023-05-10T00:00:00+00:00 [running]> on host nizam-HP-15-Notebook-PC
[2023-05-11T00:20:41.207+0530] {taskinstance.py:1568} INFO - Exporting env vars: AIRFLOW_CTX_DAG_OWNER='airflow' AIRFLOW_CTX_DAG_ID='mongodb_to_kafka_and_consumer' AIRFLOW_CTX_TASK_ID='consume_from_kafka_task' AIRFLOW_CTX_EXECUTION_DATE='2023-05-10T00:00:00+00:00' AIRFLOW_CTX_TRY_NUMBER='2' AIRFLOW_CTX_DAG_RUN_ID='scheduled__2023-05-10T00:00:00+00:00'
[2023-05-11T00:20:41.211+0530] {conn.py:380} INFO - <BrokerConnection node_id=bootstrap-0 host=localhost:9092 <connecting> [IPv4 ('127.0.0.1', 9092)]>: connecting to localhost:9092 [('127.0.0.1', 9092) IPv4]
[2023-05-11T00:20:41.211+0530] {conn.py:1205} INFO - Probing node bootstrap-0 broker version
[2023-05-11T00:20:41.212+0530] {conn.py:418} ERROR - Connect attempt to <BrokerConnection node_id=bootstrap-0 host=localhost:9092 <connecting> [IPv4 ('127.0.0.1', 9092)]> returned error 111. Disconnecting.
[2023-05-11T00:20:41.212+0530] {conn.py:919} INFO - <BrokerConnection node_id=bootstrap-0 host=localhost:9092 <connecting> [IPv4 ('127.0.0.1', 9092)]>: Closing connection. KafkaConnectionError: 111 ECONNREFUSED
[2023-05-11T00:20:41.261+0530] {conn.py:380} INFO - <BrokerConnection node_id=bootstrap-0 host=localhost:9092 <connecting> [IPv4 ('127.0.0.1', 9092)]>: connecting to localhost:9092 [('127.0.0.1', 9092) IPv4]
[2023-05-11T00:20:41.261+0530] {conn.py:418} ERROR - Connect attempt to <BrokerConnection node_id=bootstrap-0 host=localhost:9092 <connecting> [IPv4 ('127.0.0.1', 9092)]> returned error 111. Disconnecting.
[2023-05-11T00:20:41.262+0530] {conn.py:919} INFO - <BrokerConnection node_id=bootstrap-0 host=localhost:9092 <connecting> [IPv4 ('127.0.0.1', 9092)]>: Closing connection. KafkaConnectionError: 111 ECONNREFUSED
[2023-05-11T00:20:41.262+0530] {taskinstance.py:1847} ERROR - Task failed with exception
Traceback (most recent call last):
  File "/home/nizam/env_airflow/lib/python3.10/site-packages/airflow/operators/python.py", line 181, in execute
    return_value = self.execute_callable()
  File "/home/nizam/env_airflow/lib/python3.10/site-packages/airflow/operators/python.py", line 198, in execute_callable
    return self.python_callable(*self.op_args, **self.op_kwargs)
  File "/home/nizam/airflow/dags/mongokafka.py", line 59, in consume_from_kafka
    consumer = KafkaConsumer(
  File "/home/nizam/env_airflow/lib/python3.10/site-packages/kafka/consumer/group.py", line 356, in __init__
    self._client = KafkaClient(metrics=self._metrics, **self.config)
  File "/home/nizam/env_airflow/lib/python3.10/site-packages/kafka/client_async.py", line 244, in __init__
    self.config['api_version'] = self.check_version(timeout=check_timeout)
  File "/home/nizam/env_airflow/lib/python3.10/site-packages/kafka/client_async.py", line 900, in check_version
    raise Errors.NoBrokersAvailable()
kafka.errors.NoBrokersAvailable: NoBrokersAvailable
[2023-05-11T00:20:41.269+0530] {taskinstance.py:1368} INFO - Marking task as FAILED. dag_id=mongodb_to_kafka_and_consumer, task_id=consume_from_kafka_task, execution_date=20230510T000000, start_date=20230510T185041, end_date=20230510T185041
[2023-05-11T00:20:41.280+0530] {standard_task_runner.py:104} ERROR - Failed to execute job 36 for task consume_from_kafka_task (NoBrokersAvailable; 6897)
[2023-05-11T00:20:41.296+0530] {local_task_job_runner.py:232} INFO - Task exited with return code 1
[2023-05-11T00:20:41.311+0530] {taskinstance.py:2674} INFO - 0 downstream tasks scheduled from follow-on schedule check
